Workbook

Sheet Sheet1
A1: Location | B1: Date | C1: Item Name | D1: Size Name | E1: Opening Qty
A2: Head Office | B2: 45748 | C2: 06 ROSE VODKA | D2: 750-650 ML | E2: 10
A3: Head Office | B3: 45748 | C3: 100 PIPERS 12 YO BLENDED SCOTCH | D3: 180 ML | E3: 5
A4: Head Office | B4: 45748 | C4: 100 PIPERS 12 YO BLENDED SCOTCH | D4: 750-650 ML | E4: 5
A5: Head Office | B5: 45748 | C5: 100 PIPERS SCOTCH | D5: 180 ML | E5: 5
A6: Head Office | B6: 45748 | C6: 100 PIPERS SCOTCH | D6: 375-500 ML | E6: 15
A7: Head Office | B7: 45748 | C7: 100 PIPERS SCOTCH | D7: 750-650 ML | E7: 15
A8: Head Office | B8: 45748 | C8: 100 PIPERS SCOTCH 8 YEAR | D8: 180 ML | E8: 20
A9: Head Office | B9: 45748 | C9: 100 PIPERS SCOTCH 8 YEAR | D9: 750-650 ML | E9: 20
A10: store-4 | B10: 45748 | C10: 06 ROSE VODKA | D10: 750-650 ML | E10: 10
A11: store-4 | B11: 45748 | C11: 100 PIPERS 12 YO BLENDED SCOTCH | D11: 180 ML | E11: 5
A12: store-4 | B12: 45748 | C12: 100 PIPERS 12 YO BLENDED SCOTCH | D12: 750-650 ML | E12: 5
A13: store-4 | B13: 45748 | C13: 100 PIPERS SCOTCH | D13: 180 ML | E13: 5
... A17: store-4 | B17: 45748 | C17: 100 PIPERS SCOTCH 8 YEAR | D17: 750-650 ML | E17: 20

Sheet Sheet2
A1: Item Name | B1: Size Name | C1: Purchase Price | D1: MRP
A2: 06 Rose Vodka | B2: 750-650 ML | C2: 5331.23 | D2: 5980 | E2: 06 ROSE VODKA
A3: 100 Pipers 12 Yo Blended Scotch | B3: 180 ML | C3: 532.94 | D3: 600 | E3: 100 PIPERS 12 YO BLENDED SCOTCH
A4: 100 Pipers 12 Yo Blended Scotch | B4: 750-650 ML | C4: 2141.14 | D4: 2400 | E4: 100 PIPERS 12 YO BLENDED SCOTCH
A5: 100 Pipers Scotch | B5: 180 ML | C5: 368.75 | D5: 420 | E5: 100 PIPERS SCOTCH
A6: 100 Pipers Scotch | B6: 375-500 ML | C6: 754.58 | D6: 850 | E6: 100 PIPERS SCOTCH
A7: 100 Pipers Scotch | B7: 750-650 ML | C7: 1498.23 | D7: 1680 | E7: 100 PIPERS SCOTCH
A8: 100 Pipers Scotch 8 Year | B8: 180 ML | C8: 515.14 | D8: 580 | E8: 100 PIPERS SCOTCH 8 YEAR
A9: 100 Pipers Scotch 8 Year | B9: 750-650 ML | C9: 2054.72 | D9: 2310 | E9: 100 PIPERS SCOTCH 8 YEAR
A10: 1943 Virasat Indian Whisky | B10: 750-650 ML | C10: 4077.84 | D10: 4570 | E10: 1943 VIRASAT INDIAN WHISKY
A11: 1965 Espresso Coffee Premium Dark Rum | B11: 180 ML | C11: 215.51 | D11: 250 | E11: 1965 ESPRESSO COFFEE PREMIUM DARK RUM
A12: 1965 Espresso Coffee Premium Dark Rum | B12: 375-500 ML | C12: 428.98 | D12: 490 | E12: 1965 ESPRESSO COFFEE PREMIUM DARK RUM
A13: 1965 Espresso Coffee Premium Dark Rum | B13: 750-650 ML | C13: 847.95 | D13: 950 | E13: 1965 ESPRESSO COFFEE PREMIUM DARK RUM
... A1076: Wonder Wine | B1076: 330 ML | C1076: 161.09 | D1076: 190 | E1076: WONDER WINE

Sheet Sheet3
A1: Bhrum Lemon White Rum (200) | B1: Bhrum Lemon White Rum
A2: Bhrum Lemon White Rum (400) | B2: Bhrum Lemon White Rum
A3: Bhrum Lemon White Rum (780) | B3: Bhrum Lemon White Rum
A4: Big Ben London (140) | B4: Big Ben London
A5: Big Ben London (290) | B5: Big Ben London
A6: Black Dog Centenary Scotch (370) | B6: Black Dog Centenary Scotch
A7: Black Dog Centenary Scotch (760) | B7: Black Dog Centenary Scotch
A8: Black Dog Centenary Scotch (1510) | B8: Black Dog Centenary Scotch
A9: Black Dog Millard 14y Blended (3880) | B9: Black Dog Millard 14y Blended
A10: Black Dog Triple Gold (550) | B10: Black Dog Triple Gold
A11: Black Dog Triple Gold (1130) | B11: Black Dog Triple Gold
A12: Black Dog Triple Gold (2200) | B12: Black Dog Triple Gold
... A34: Bora Bora Vodka Cranberry (770) | B34: Bora Bora Vodka Cranberry
A35: Bowmore 12 Y.O 700 (3920) | B35: Bowmore 12 YO | D35: Bowmore 12 YO
A36: BP Four Elements (250) | B36: BP Four Elements
A37: BP Four Elements (510) | B37: BP Four Elements
A38: BP Four Elements (1000) | B38: BP Four Elements
A39: BP Four Elements 90 (130) | B39: BP Four Elements | C39: BP Four Elements
A40: BP Rare Premium Whisky 090 | B40: BP Rare Premium Whisky
A41: BP Rare Premium Whisky | B41: BP Rare Premium Whisky
A42: BP Rare Premium Whisky (480) | B42: BP Rare Premium Whisky
A43: BP Rare Premium Whisky (930) | B43: BP Rare Premium Whisky
A44: BP Reserve Collection | B44: BP Reserve Collection
A45: BP Reserve Collection | B45: BP Reserve Collection
A46: BP Reserve Collection | B46: BP Reserve Collection
A47: BP Reserve Collection 90(130) | B47: BP Reserve Collection
A48: Brancott Estate Sauvignon Blcnc (1550) | B48: Brancott Estate Sauvignon Blcnc
A49: Brothers And Co. Finest Blended Whisky | B49: Brothers And Co. Finest Blended Whisky
A50: Brothers And Co. Finest Blended Whisky | B50: Brothers And Co. Finest Blended Whisky
A51: Brothers And Co. Finest Blended Whisky | B51: Brothers And Co. Finest Blended Whisky
A52: Brothers And Co. Finest Blended Whisky 90 Ne | B52: Brothers And Co. Finest Blended Whisky 90 Ne | C52: Brothers And Co. Finest Blended Whisky 90 Ne
A53: Budwiser Magnum American Whisky (1900) | B53: Budwiser Magnum American Whisky
A54: Buen Tequila (2410) | B54: Buen Tequila
A55: Bulldog London Gin (2430) | B55: Bulldog London Gin
A56: Burnetts London Dry Gin | B56: Burnetts London Dry Gin
A57: Bush Ballad Merlot Wine (2260) | B57: Bush Ballad Merlot Wine
A58: Bush Ballad Shiraz/Chardonnay (2320) | B58: Bush Ballad Shiraz/Chardonnay
A59: Bush Ballad Shiraz Wine (1) | B59: Bush Ballad Shiraz Wine
A60: Bush Malt 12yo (4970) | B60: Bush Malt 12YO
A61: Bushmills 16 Years 700 (19520) | B61: Bushmills 16 Years
...

Sheet Original
A1: Brand Name | C1: Average Purchase Rate | D1: Estimated Mrp | E1: Item Name | F1: Size Name | G1: Purchase Price | H1: MRP
A2: 06 Rose Vodka | B2: 700 ml | C2: 5331.23 | D2: 5980 | E2: =VLOOKUP(A2,Sheet2!A:E,5,) -> 06 ROSE VODKA | F2: 750-650 ML | G2: 5331.23 | H2: 5980
A3: 100 Pipers 12 Yo Blended Scotch | B3: 180ml | C3: 532.94 | D3: 600 | E3: =VLOOKUP(A3,Sheet2!A:E,5,) -> 100 PIPERS 12 YO BLENDED SCOTCH | F3: 180 ML | G3: 532.94 | H3: 600
A4: 100 Pipers 12 Yo Blended Scotch | B4: 750 ml | C4: 2141.14 | D4: 2400 | E4: =VLOOKUP(A4,Sheet2!A:E,5,) -> 100 PIPERS 12 YO BLENDED SCOTCH | F4: 750-650 ML | G4: 2141.14 | H4: 2400
A5: 100 Pipers Scotch | B5: 180ml | C5: 368.75 | D5: 420 | E5: =VLOOKUP(A5,Sheet2!A:E,5,) -> 100 PIPERS SCOTCH | F5: 180 ML | G5: 368.75 | H5: 420
A6: 100 Pipers Scotch | B6: 375 ml | C6: 754.58 | D6: 850 | E6: =VLOOKUP(A6,Sheet2!A:E,5,) -> 100 PIPERS SCOTCH | F6: 375-500 ML | G6: 754.58 | H6: 850
A7: 100 Pipers Scotch | B7: 750 ml | C7: 1498.23 | D7: 1680 | E7: =VLOOKUP(A7,Sheet2!A:E,5,) -> 100 PIPERS SCOTCH | F7: 750-650 ML | G7: 1498.23 | H7: 1680
A8: 100 Pipers Scotch 8 Year | B8: 180ml | C8: 515.14 | D8: 580 | E8: =VLOOKUP(A8,Sheet2!A:E,5,) -> 100 PIPERS SCOTCH 8 YEAR | F8: 180 ML | G8: 515.14 | H8: 580
A9: 100 Pipers Scotch 8 Year | B9: 750 ml | C9: 2054.72 | D9: 2310 | E9: =VLOOKUP(A9,Sheet2!A:E,5,) -> 100 PIPERS SCOTCH 8 YEAR | F9: 750-650 ML | G9: 2054.72 | H9: 2310
A10: 1943 Virasat Indian Whisky | B10: 750 ml | C10: 4077.84 | D10: 4570 | E10: =VLOOKUP(A10,Sheet2!A:E,5,) -> 1943 VIRASAT INDIAN WHISKY | F10: 750-650 ML | G10: 4077.84 | H10: 4570
A11: 1965 Espresso Coffee Premium Dark Rum | B11: 180ml | C11: 215.51 | D11: 250 | E11: =VLOOKUP(A11,Sheet2!A:E,5,) -> 1965 ESPRESSO COFFEE PREMIUM DARK RUM | F11: 180 ML | G11: 215.51 | H11: 250
A12: 1965 Espresso Coffee Premium Dark Rum | B12: 375 ml | C12: 428.98 | D12: 490 | E12: =VLOOKUP(A12,Sheet2!A:E,5,) -> 1965 ESPRESSO COFFEE PREMIUM DARK RUM | F12: 375-500 ML | G12: 428.98 | H12: 490
A13: 1965 Espresso Coffee Premium Dark Rum | B13: 750 ml | C13: 847.95 | D13: 950 | E13: =VLOOKUP(A13,Sheet2!A:E,5,) -> 1965 ESPRESSO COFFEE PREMIUM DARK RUM | F13: 750-650 ML | G13: 847.95 | H13: 950
... A1076: Wonder Wine | B1076: 330 ml | C1076: 161.09 | D1076: 190 | E1076: =VLOOKUP(A1076,Sheet2!A:E,5,) -> WONDER WINE | F1076: 330 ML | G1076: 161.09 | H1076: 190
